Workbook

Sheet Tasas_Informalidad_2007-2042
A1: TASAS DE INFORMALIDAD LABORAL: HISTÓRICO Y PROYECCIÓN | 2007–2042 (% Ocupados Informales / Total Ocupados)
A3: Histórico 2007–2026: DANE — Gran Encuesta Integrada de Hogares (GEIH). 2007–2024: serie anual observada. 2025: promedio trimestres móviles Ene-mar a Oct-dic 2025. 2026: dato parcial Ene-mar 2026 (no promedio anual). Proyección 2026–2042: Modelo Lee-Carter (1992), escenario central — ARIMA(0,1,0) con deriva. Varianza explicada (1er factor SVD): 99.1%.
A5: Ciudad | B5: ◀ HISTÓRICO — DANE GEIH | 2007–2026 ▶ | V5: ◀ PROYECCIÓN LEE-CARTER | 2026–2042 ▶
B6: 2007 | C6: 2008 | D6: 2009 | E6: 2010 | F6: 2011 | G6: 2012 | H6: 2013 | I6: 2014 | J6: 2015 | K6: 2016 | L6: 2017 | M6: 2018 | N6: 2019 | O6: 2020 | P6: 2021 | Q6: 2022 | R6: 2023 | S6: 2024 | T6: 2025 | U6: 2026 | V6: 2026 | W6: 2027 | X6: 2028 | Y6: 2029 | Z6: 2030 | AA6: 2031 | AB6: 2032 | AC6: 2033 | AD6: 2034 | AE6: 2035 | AF6: 2036 | AG6: 2037 | AH6: 2038 | AI6: 2039 | AJ6: 2040 | AK6: 2041 | AL6: 2042
A7: ='Historico_GEIH_2007-2026'!A6 -> Bogotá D.C. | B7: ='Historico_GEIH_2007-2026'!B6 -> 47.8 | C7: ='Historico_GEIH_2007-2026'!C6 -> 47.2 | D7: ='Historico_GEIH_2007-2026'!D6 -> 46.8 | E7: ='Historico_GEIH_2007-2026'!E6 -> 46.1 | F7: ='Historico_GEIH_2007-2026'!F6 -> 45.5 | G7: ='Historico_GEIH_2007-2026'!G6 -> 44.8 | H7: ='Historico_GEIH_2007-2026'!H6 -> 44.2 | ... U7: ='Historico_GEIH_2007-2026'!U6 -> 34.0393 | V7: =Tasas_Informalidad_Proy!B6 -> 41.3942 | W7: =Tasas_Informalidad_Proy!C6 -> 41.072 | X7: =Tasas_Informalidad_Proy!D6 -> 40.7523 | Y7: =Tasas_Informalidad_Proy!E6 -> 40.4351 | Z7: =Tasas_Informalidad_Proy!F6 -> 40.1204 | AA7: =Tasas_Informalidad_Proy!G6 -> 39.8081 | AB7: =Tasas_Informalidad_Proy!H6 -> 39.4982 | AC7: =Tasas_Informalidad_Proy!I6 -> 39.1908 | ... AL7: =Tasas_Informalidad_Proy!R6 -> 36.5293
A8: ='Historico_GEIH_2007-2026'!A7 -> Medellín | B8: ='Historico_GEIH_2007-2026'!B7 -> 50.2 | C8: ='Historico_GEIH_2007-2026'!C7 -> 49.5 | D8: ='Historico_GEIH_2007-2026'!D7 -> 48.8 | E8: ='Historico_GEIH_2007-2026'!E7 -> 47.9 | F8: ='Historico_GEIH_2007-2026'!F7 -> 47.1 | G8: ='Historico_GEIH_2007-2026'!G7 -> 46.2 | H8: ='Historico_GEIH_2007-2026'!H7 -> 45.3 | ... U8: ='Historico_GEIH_2007-2026'!U7 -> 38.4318 | V8: =Tasas_Informalidad_Proy!B7 -> 41.6713 | W8: =Tasas_Informalidad_Proy!C7 -> 41.2616 | X8: =Tasas_Informalidad_Proy!D7 -> 40.8561 | Y8: =Tasas_Informalidad_Proy!E7 -> 40.4545 | Z8: =Tasas_Informalidad_Proy!F7 -> 40.0568 | AA8: =Tasas_Informalidad_Proy!G7 -> 39.6631 | AB8: =Tasas_Informalidad_Proy!H7 -> 39.2732 | AC8: =Tasas_Informalidad_Proy!I7 -> 38.8871 | ... AL8: =Tasas_Informalidad_Proy!R7 -> 35.5791
A9: ='Historico_GEIH_2007-2026'!A8 -> Cali | B9: ='Historico_GEIH_2007-2026'!B8 -> 56.5 | C9: ='Historico_GEIH_2007-2026'!C8 -> 55.8 | D9: ='Historico_GEIH_2007-2026'!D8 -> 55.1 | E9: ='Historico_GEIH_2007-2026'!E8 -> 54.5 | F9: ='Historico_GEIH_2007-2026'!F8 -> 53.8 | G9: ='Historico_GEIH_2007-2026'!G8 -> 53.1 | H9: ='Historico_GEIH_2007-2026'!H8 -> 52.5 | ... U9: ='Historico_GEIH_2007-2026'!U8 -> 47.0456 | V9: =Tasas_Informalidad_Proy!B8 -> 48.8136 | W9: =Tasas_Informalidad_Proy!C8 -> 48.4327 | X9: =Tasas_Informalidad_Proy!D8 -> 48.0548 | Y9: =Tasas_Informalidad_Proy!E8 -> 47.6798 | Z9: =Tasas_Informalidad_Proy!F8 -> 47.3078 | AA9: =Tasas_Informalidad_Proy!G8 -> 46.9386 | AB9: =Tasas_Informalidad_Proy!H8 -> 46.5724 | AC9: =Tasas_Informalidad_Proy!I8 -> 46.209 | ... AL9: =Tasas_Informalidad_Proy!R8 -> 43.0633
A10: ='Historico_GEIH_2007-2026'!A9 -> Barranquilla | B10: ='Historico_GEIH_2007-2026'!B9 -> 61.9 | C10: ='Historico_GEIH_2007-2026'!C9 -> 61.2 | D10: ='Historico_GEIH_2007-2026'!D9 -> 60.5 | E10: ='Historico_GEIH_2007-2026'!E9 -> 59.8 | F10: ='Historico_GEIH_2007-2026'!F9 -> 59.2 | G10: ='Historico_GEIH_2007-2026'!G9 -> 58.4 | H10: ='Historico_GEIH_2007-2026'!H9 -> 57.9 | ... U10: ='Historico_GEIH_2007-2026'!U9 -> 51.6121 | V10: =Tasas_Informalidad_Proy!B9 -> 55.1804 | W10: =Tasas_Informalidad_Proy!C9 -> 54.8516 | X10: =Tasas_Informalidad_Proy!D9 -> 54.5248 | Y10: =Tasas_Informalidad_Proy!E9 -> 54.1999 | Z10: =Tasas_Informalidad_Proy!F9 -> 53.8769 | AA10: =Tasas_Informalidad_Proy!G9 -> 53.5558 | AB10: =Tasas_Informalidad_Proy!H9 -> 53.2367 | AC10: =Tasas_Informalidad_Proy!I9 -> 52.9195 | ... AL10: =Tasas_Informalidad_Proy!R9 -> 50.1481
A11: ='Historico_GEIH_2007-2026'!A10 -> Bucaramanga | B11: ='Historico_GEIH_2007-2026'!B10 -> 69.2 | C11: ='Historico_GEIH_2007-2026'!C10 -> 68.5 | D11: ='Historico_GEIH_2007-2026'!D10 -> 67.8 | E11: ='Historico_GEIH_2007-2026'!E10 -> 67.1 | F11: ='Historico_GEIH_2007-2026'!F10 -> 66.4 | G11: ='Historico_GEIH_2007-2026'!G10 -> 65.5 | H11: ='Historico_GEIH_2007-2026'!H10 -> 64.8 | ... U11: ='Historico_GEIH_2007-2026'!U10 -> 42.6957 | V11: =Tasas_Informalidad_Proy!B10 -> 61.0305 | W11: =Tasas_Informalidad_Proy!C10 -> 60.6248 | X11: =Tasas_Informalidad_Proy!D10 -> 60.2218 | Y11: =Tasas_Informalidad_Proy!E10 -> 59.8215 | Z11: =Tasas_Informalidad_Proy!F10 -> 59.4238 | AA11: =Tasas_Informalidad_Proy!G10 -> 59.0288 | AB11: =Tasas_Informalidad_Proy!H10 -> 58.6364 | AC11: =Tasas_Informalidad_Proy!I10 -> 58.2466 | ... AL11: =Tasas_Informalidad_Proy!R10 -> 54.8529
A12: ='Historico_GEIH_2007-2026'!A11 -> Manizales | B12: ='Historico_GEIH_2007-2026'!B11 -> 56.1 | C12: ='Historico_GEIH_2007-2026'!C11 -> 55.4 | D12: ='Historico_GEIH_2007-2026'!D11 -> 54.7 | E12: ='Historico_GEIH_2007-2026'!E11 -> 54.1 | F12: ='Historico_GEIH_2007-2026'!F11 -> 53.4 | G12: ='Historico_GEIH_2007-2026'!G11 -> 52.6 | H12: ='Historico_GEIH_2007-2026'!H11 -> 52.1 | ... U12: ='Historico_GEIH_2007-2026'!U11 -> 35.1318 | V12: =Tasas_Informalidad_Proy!B11 -> 48.5963 | W12: =Tasas_Informalidad_Proy!C11 -> 48.2274 | X12: =Tasas_Informalidad_Proy!D11 -> 47.8614 | Y12: =Tasas_Informalidad_Proy!E11 -> 47.4981 | Z12: =Tasas_Informalidad_Proy!F11 -> 47.1375 | AA12: =Tasas_Informalidad_Proy!G11 -> 46.7797 | AB12: =Tasas_Informalidad_Proy!H11 -> 46.4247 | AC12: =Tasas_Informalidad_Proy!I11 -> 46.0723 | ... AL12: =Tasas_Informalidad_Proy!R11 -> 43.0188
A13: ='Historico_GEIH_2007-2026'!A12 -> Pasto | B13: ='Historico_GEIH_2007-2026'!B12 -> 73.8 | C13: ='Historico_GEIH_2007-2026'!C12 -> 73.1 | D13: ='Historico_GEIH_2007-2026'!D12 -> 72.5 | E13: ='Historico_GEIH_2007-2026'!E12 -> 72 | F13: ='Historico_GEIH_2007-2026'!F12 -> 71.4 | G13: ='Historico_GEIH_2007-2026'!G12 -> 70.5 | H13: ='Historico_GEIH_2007-2026'!H12 -> 70.2 | ... U13: ='Historico_GEIH_2007-2026'!U12 -> 54.4881 | V13: =Tasas_Informalidad_Proy!B12 -> 67.8754 | W13: =Tasas_Informalidad_Proy!C12 -> 67.5826 | X13: =Tasas_Informalidad_Proy!D12 -> 67.2911 | Y13: =Tasas_Informalidad_Proy!E12 -> 67.0008 | Z13: =Tasas_Informalidad_Proy!F12 -> 66.7118 | AA13: =Tasas_Informalidad_Proy!G12 -> 66.4241 | AB13: =Tasas_Informalidad_Proy!H12 -> 66.1376 | AC13: =Tasas_Informalidad_Proy!I12 -> 65.8523 | ... AL13: =Tasas_Informalidad_Proy!R12 -> 63.3395
A14: ='Historico_GEIH_2007-2026'!A13 -> Pereira | B14: ='Historico_GEIH_2007-2026'!B13 -> 63.5 | C14: ='Historico_GEIH_2007-2026'!C13 -> 62.8 | D14: ='Historico_GEIH_2007-2026'!D13 -> 62.1 | E14: ='Historico_GEIH_2007-2026'!E13 -> 61.5 | F14: ='Historico_GEIH_2007-2026'!F13 -> 60.8 | G14: ='Historico_GEIH_2007-2026'!G13 -> 60 | H14: ='Historico_GEIH_2007-2026'!H13 -> 59.5 | ... U14: ='Historico_GEIH_2007-2026'!U13 -> 39.3332 | V14: =Tasas_Informalidad_Proy!B13 -> 56.5056 | W14: =Tasas_Informalidad_Proy!C13 -> 56.1586 | X14: =Tasas_Informalidad_Proy!D13 -> 55.8138 | Y14: =Tasas_Informalidad_Proy!E13 -> 55.471 | Z14: =Tasas_Informalidad_Proy!F13 -> 55.1303 | AA14: =Tasas_Informalidad_Proy!G13 -> 54.7918 | AB14: =Tasas_Informalidad_Proy!H13 -> 54.4553 | AC14: =Tasas_Informalidad_Proy!I13 -> 54.1209 | ... AL14: =Tasas_Informalidad_Proy!R13 -> 51.202
A15: ='Historico_GEIH_2007-2026'!A14 -> Cúcuta | B15: ='Historico_GEIH_2007-2026'!B14 -> 76.9 | C15: ='Historico_GEIH_2007-2026'!C14 -> 76.2 | D15: ='Historico_GEIH_2007-2026'!D14 -> 75.5 | E15: ='Historico_GEIH_2007-2026'!E14 -> 74.8 | F15: ='Historico_GEIH_2007-2026'!F14 -> 74.1 | G15: ='Historico_GEIH_2007-2026'!G14 -> 73.2 | H15: ='Historico_GEIH_2007-2026'!H14 -> 72.5 | ... U15: ='Historico_GEIH_2007-2026'!U14 -> 62.2944 | V15: =Tasas_Informalidad_Proy!B14 -> 69.0362 | W15: =Tasas_Informalidad_Proy!C14 -> 68.645 | X15: =Tasas_Informalidad_Proy!D14 -> 68.256 | Y15: =Tasas_Informalidad_Proy!E14 -> 67.8693 | Z15: =Tasas_Informalidad_Proy!F14 -> 67.4847 | AA15: =Tasas_Informalidad_Proy!G14 -> 67.1023 | AB15: =Tasas_Informalidad_Proy!H14 -> 66.722 | AC15: =Tasas_Informalidad_Proy!I14 -> 66.344 | ... AL15: =Tasas_Informalidad_Proy!R14 -> 63.0362
A16: ='Historico_GEIH_2007-2026'!A15 -> Ibagué | B16: ='Historico_GEIH_2007-2026'!B15 -> 66.1 | C16: ='Historico_GEIH_2007-2026'!C15 -> 65.4 | D16: ='Historico_GEIH_2007-2026'!D15 -> 64.7 | E16: ='Historico_GEIH_2007-2026'!E15 -> 64.1 | F16: ='Historico_GEIH_2007-2026'!F15 -> 63.4 | G16: ='Historico_GEIH_2007-2026'!G15 -> 63 | H16: ='Historico_GEIH_2007-2026'!H15 -> 62.5 | ... U16: ='Historico_GEIH_2007-2026'!U15 -> 45.3417 | V16: =Tasas_Informalidad_Proy!B15 -> 59.7518 | W16: =Tasas_Informalidad_Proy!C15 -> 59.4373 | X16: =Tasas_Informalidad_Proy!D15 -> 59.1246 | Y16: =Tasas_Informalidad_Proy!E15 -> 58.8134 | Z16: =Tasas_Informalidad_Proy!F15 -> 58.5039 | AA16: =Tasas_Informalidad_Proy!G15 -> 58.1961 | AB16: =Tasas_Informalidad_Proy!H15 -> 57.8898 | AC16: =Tasas_Informalidad_Proy!I15 -> 57.5852 | ... AL16: =Tasas_Informalidad_Proy!R15 -> 54.9146
A17: ='Historico_GEIH_2007-2026'!A16 -> Montería | B17: ='Historico_GEIH_2007-2026'!B16 -> 80.2 | C17: ='Historico_GEIH_2007-2026'!C16 -> 79.5 | D17: ='Historico_GEIH_2007-2026'!D16 -> 78.8 | E17: ='Historico_GEIH_2007-2026'!E16 -> 78.2 | F17: ='Historico_GEIH_2007-2026'!F16 -> 77.5 | G17: ='Historico_GEIH_2007-2026'!G16 -> 77 | H17: ='Historico_GEIH_2007-2026'!H16 -> 76.5 | ... U17: ='Historico_GEIH_2007-2026'!U16 -> 55.8173 | V17: =Tasas_Informalidad_Proy!B16 -> 73.328 | W17: =Tasas_Informalidad_Proy!C16 -> 72.9845 | X17: =Tasas_Informalidad_Proy!D16 -> 72.6426 | Y17: =Tasas_Informalidad_Proy!E16 -> 72.3023 | Z17: =Tasas_Informalidad_Proy!F16 -> 71.9636 | AA17: =Tasas_Informalidad_Proy!G16 -> 71.6265 | AB17: =Tasas_Informalidad_Proy!H16 -> 71.2909 | AC17: =Tasas_Informalidad_Proy!I16 -> 70.957 | ... AL17: =Tasas_Informalidad_Proy!R16 -> 68.0208
A18: ='Historico_GEIH_2007-2026'!A17 -> Cartagena | B18: ='Historico_GEIH_2007-2026'!B17 -> 61.5 | C18: ='Historico_GEIH_2007-2026'!C17 -> 60.8 | D18: ='Historico_GEIH_2007-2026'!D17 -> 60.2 | E18: ='Historico_GEIH_2007-2026'!E17 -> 59.5 | F18: ='Historico_GEIH_2007-2026'!F17 -> 58.8 | G18: ='Historico_GEIH_2007-2026'!G17 -> 58.2 | H18: ='Historico_GEIH_2007-2026'!H17 -> 57.8 | ... U18: ='Historico_GEIH_2007-2026'!U17 -> 45.7121 | V18: =Tasas_Informalidad_Proy!B17 -> 55.1 | W18: =Tasas_Informalidad_Proy!C17 -> 54.7844 | X18: =Tasas_Informalidad_Proy!D17 -> 54.4707 | Y18: =Tasas_Informalidad_Proy!E17 -> 54.1588 | Z18: =Tasas_Informalidad_Proy!F17 -> 53.8487 | AA18: =Tasas_Informalidad_Proy!G17 -> 53.5403 | AB18: =Tasas_Informalidad_Proy!H17 -> 53.2337 | AC18: =Tasas_Informalidad_Proy!I17 -> 52.9288 | ... AL18: =Tasas_Informalidad_Proy!R17 -> 50.2626
... A29: ='Historico_GEIH_2007-2026'!A28 -> Sincelejo | B29: ='Historico_GEIH_2007-2026'!B28 -> 73.9 | C29: ='Historico_GEIH_2007-2026'!C28 -> 73.2 | D29: ='Historico_GEIH_2007-2026'!D28 -> 72.5 | E29: ='Historico_GEIH_2007-2026'!E28 -> 71.9 | F29: ='Historico_GEIH_2007-2026'!F28 -> 71.2 | G29: ='Historico_GEIH_2007-2026'!G28 -> 70.5 | H29: ='Historico_GEIH_2007-2026'!H28 -> 70.1 | ... U29: ='Historico_GEIH_2007-2026'!U28 -> 67.2378 | V29: =Tasas_Informalidad_Proy!B28 -> 67.2907 | W29: =Tasas_Informalidad_Proy!C28 -> 66.9637 | X29: =Tasas_Informalidad_Proy!D28 -> 66.6383 | Y29: =Tasas_Informalidad_Proy!E28 -> 66.3145 | Z29: =Tasas_Informalidad_Proy!F28 -> 65.9923 | AA29: =Tasas_Informalidad_Proy!G28 -> 65.6716 | AB29: =Tasas_Informalidad_Proy!H28 -> 65.3525 | AC29: =Tasas_Informalidad_Proy!I28 -> 65.035 | ... AL29: =Tasas_Informalidad_Proy!R28 -> 62.2456
A32: ='Historico_GEIH_2007-2026'!A31 -> Índice κₜ Lee-Carter (histórico) | B32: ='Historico_GEIH_2007-2026'!B31 -> 1.357218 | C32: ='Historico_GEIH_2007-2026'!C31 -> 1.12127 | D32: ='Historico_GEIH_2007-2026'!D31 -> 0.890735 | E32: ='Historico_GEIH_2007-2026'!E31 -> 0.662383 | F32: ='Historico_GEIH_2007-2026'!F31 -> 0.417758 | G32: ='Historico_GEIH_2007-2026'!G31 -> 0.163599 | H32: ='Historico_GEIH_2007-2026'!H31 -> -0.031979 | ... U32: ='Historico_GEIH_2007-2026'!U31 -> -5.6456896

Sheet Portada
A1: PROYECCIÓN DE TASAS DE INFORMALIDAD LABORAL
B10: Ciudades cubiertas: | D10: 23 ciudades de cobertura GEIH-DANE
B11: Horizonte de proyección: | D11: 2026 – 2042
B12: Metodología: | D12: Modelo Lee-Carter (1992) adaptado — igual criterio DANE-PPED 2025
B13: Proyección κₜ: | D13: Random Walk con Deriva — ARIMA(0,1,0) con intercepto
B14: Insumo poblacional: | D14: DANE PPED 2025 — PPED-AreaSexoEdadMun-2018-2042_VP
B15: Tasas históricas: | D15: DANE GEIH, promedio anual 2007-2024
B16: Producido por: | D16: Prométricas — Procesamiento estadístico, junio 2026
B17: Criterio de informalidad: | D17: Ocupados en establecimientos ≤ 5 trabajadores (DANE GEIH)
B18: Varianza explicada (1er factor): | D18: 99.1%

Sheet Tasas_Informalidad_Proy
A1: TASAS DE INFORMALIDAD LABORAL PROYECTADAS — ESCENARIO CENTRAL | 2026–2042 (% Ocupados Informales / Total Ocupados)
A3: Valores proyectados por modelo Lee-Carter (1992). Varianza explicada por 1er componente SVD: 99.1%. Fuente histórica: DANE GEIH 2007-2024.
A5: Ciudad | B5: 2026 | C5: 2027 | D5: 2028 | E5: 2029 | F5: 2030 | G5: 2031 | H5: 2032 | I5: 2033 | J5: 2034 | K5: 2035 | L5: 2036 | M5: 2037 | N5: 2038 | O5: 2039 | P5: 2040 | Q5: 2041 | R5: 2042
A6: Bogotá D.C. | B6: 41.3942 | C6: 41.072 | D6: 40.7523 | E6: 40.4351 | F6: 40.1204 | G6: 39.8081 | H6: 39.4982 | I6: 39.1908 | J6: 38.8857 | K6: 38.5831 | L6: 38.2827 | M6: 37.9848 | N6: 37.6891 | O6: 37.3958 | P6: 37.1047 | Q6: 36.8159 | R6: 36.5293
A7: Medellín | B7: 41.6713 | C7: 41.2616 | D7: 40.8561 | E7: 40.4545 | F7: 40.0568 | G7: 39.6631 | H7: 39.2732 | I7: 38.8871 | J7: 38.5049 | K7: 38.1264 | L7: 37.7516 | M7: 37.3805 | N7: 37.0131 | O7: 36.6493 | P7: 36.289 | Q7: 35.9323 | R7: 35.5791
A8: Cali | B8: 48.8136 | C8: 48.4327 | D8: 48.0548 | E8: 47.6798 | F8: 47.3078 | G8: 46.9386 | H8: 46.5724 | I8: 46.209 | J8: 45.8484 | K8: 45.4906 | L8: 45.1356 | M8: 44.7835 | N8: 44.434 | O8: 44.0873 | P8: 43.7433 | Q8: 43.4019 | R8: 43.0633
A9: Barranquilla | B9: 55.1804 | C9: 54.8516 | D9: 54.5248 | E9: 54.1999 | F9: 53.8769 | G9: 53.5558 | H9: 53.2367 | I9: 52.9195 | J9: 52.6041 | K9: 52.2907 | L9: 51.9791 | M9: 51.6693 | N9: 51.3614 | O9: 51.0554 | P9: 50.7511 | Q9: 50.4487 | R9: 50.1481
A10: Bucaramanga | B10: 61.0305 | C10: 60.6248 | D10: 60.2218 | E10: 59.8215 | F10: 59.4238 | G10: 59.0288 | H10: 58.6364 | I10: 58.2466 | J10: 57.8593 | K10: 57.4747 | L10: 57.0926 | M10: 56.7131 | N10: 56.3361 | O10: 55.9616 | P10: 55.5896 | Q10: 55.22 | R10: 54.8529
A11: Manizales | B11: 48.5963 | C11: 48.2274 | D11: 47.8614 | E11: 47.4981 | F11: 47.1375 | G11: 46.7797 | H11: 46.4247 | I11: 46.0723 | J11: 45.7226 | K11: 45.3755 | L11: 45.0311 | M11: 44.6893 | N11: 44.3501 | O11: 44.0135 | P11: 43.6794 | Q11: 43.3478 | R11: 43.0188
A12: Pasto | B12: 67.8754 | C12: 67.5826 | D12: 67.2911 | E12: 67.0008 | F12: 66.7118 | G12: 66.4241 | H12: 66.1376 | I12: 65.8523 | J12: 65.5682 | K12: 65.2854 | L12: 65.0038 | M12: 64.7234 | N12: 64.4442 | O12: 64.1662 | P12: 63.8894 | Q12: 63.6139 | R12: 63.3395
A13: Pereira | B13: 56.5056 | C13: 56.1586 | D13: 55.8138 | E13: 55.471 | F13: 55.1303 | G13: 54.7918 | H13: 54.4553 | I13: 54.1209 | J13: 53.7885 | K13: 53.4582 | L13: 53.1299 | M13: 52.8036 | N13: 52.4793 | O13: 52.1571 | P13: 51.8368 | Q13: 51.5184 | R13: 51.202
A14: Cúcuta | B14: 69.0362 | C14: 68.645 | D14: 68.256 | E14: 67.8693 | F14: 67.4847 | G14: 67.1023 | H14: 66.722 | I14: 66.344 | J14: 65.968 | K14: 65.5942 | L14: 65.2225 | M14: 64.8529 | N14: 64.4855 | O14: 64.1201 | P14: 63.7567 | Q14: 63.3954 | R14: 63.0362
A15: Ibagué | B15: 59.7518 | C15: 59.4373 | D15: 59.1246 | E15: 58.8134 | F15: 58.5039 | G15: 58.1961 | H15: 57.8898 | I15: 57.5852 | J15: 57.2822 | K15: 56.9807 | L15: 56.6809 | M15: 56.3826 | N15: 56.0859 | O15: 55.7907 | P15: 55.4972 | Q15: 55.2051 | R15: 54.9146
A16: Montería | B16: 73.328 | C16: 72.9845 | D16: 72.6426 | E16: 72.3023 | F16: 71.9636 | G16: 71.6265 | H16: 71.2909 | I16: 70.957 | J16: 70.6246 | K16: 70.2937 | L16: 69.9644 | M16: 69.6367 | N16: 69.3104 | O16: 68.9857 | P16: 68.6626 | Q16: 68.3409 | R16: 68.0208
A17: Cartagena | B17: 55.1 | C17: 54.7844 | D17: 54.4707 | E17: 54.1588 | F17: 53.8487 | G17: 53.5403 | H17: 53.2337 | I17: 52.9288 | J17: 52.6257 | K17: 52.3244 | L17: 52.0247 | M17: 51.7268 | N17: 51.4306 | O17: 51.1361 | P17: 50.8433 | Q17: 50.5521 | R17: 50.2626
... A28: Sincelejo | B28: 67.2907 | C28: 66.9637 | D28: 66.6383 | E28: 66.3145 | F28: 65.9923 | G28: 65.6716 | H28: 65.3525 | I28: 65.035 | J28: 64.719 | K28: 64.4045 | L28: 64.0916 | M28: 63.7801 | N28: 63.4702 | O28: 63.1618 | P28: 62.8549 | Q28: 62.5495 | R28: 62.2456

Sheet IC_95pct
A1: INTERVALOS DE CONFIANZA AL 95% — TASAS DE INFORMALIDAD PROYECTADAS | 2026–2042
A4: Ciudad | B4: Año | C4: Escenario Central (%) | D4: Límite Inferior 95% (%) | E4: Límite Superior 95% (%) | F4: Amplitud IC (pp) | G4: PEA 15-64
A5: Bogotá D.C. | B5: 2026 | C5: 41.3942 | D5: 38.8729 | E5: 44.0789 | F5: =E5-D5 -> 5.206 | G5: =Ocupados_Proy!$D$5 -> 5694816
A6: Medellín | B6: 2026 | C6: 41.6713 | D6: 38.4888 | E6: 45.1168 | F6: =E6-D6 -> 6.628 | G6: =Ocupados_Proy!$D$6 -> 1772378
A7: Cali | B7: 2026 | C7: 48.8136 | D7: 45.8332 | E7: 51.9879 | F7: =E7-D7 -> 6.1547 | G7: =Ocupados_Proy!$D$7 -> 1576113
A8: Barranquilla | B8: 2026 | C8: 55.1804 | D8: 52.5908 | E8: 57.8975 | F8: =E8-D8 -> 5.3067 | G8: =Ocupados_Proy!$D$8 -> 864371
A9: Bucaramanga | B9: 2026 | C9: 61.0305 | D9: 57.8431 | E9: 64.3937 | F9: =E9-D9 -> 6.5506 | G9: =Ocupados_Proy!$D$9 -> 424315
A10: Manizales | B10: 2026 | C10: 48.5963 | D10: 45.7079 | E10: 51.6672 | F10: =E10-D10 -> 5.9593 | G10: =Ocupados_Proy!$D$10 -> 328451
A11: Pasto | B11: 2026 | C11: 67.8754 | D11: 65.5563 | E11: 70.2766 | F11: =E11-D11 -> 4.7203 | G11: =Ocupados_Proy!$D$11 -> 288315
A12: Pereira | B12: 2026 | C12: 56.5056 | D12: 53.7745 | E12: 59.3755 | F12: =E12-D12 -> 5.601 | G12: =Ocupados_Proy!$D$12 -> 331654
A13: Cúcuta | B13: 2026 | C13: 69.0362 | D13: 65.9522 | E13: 72.2644 | F13: =E13-D13 -> 6.3122 | G13: =Ocupados_Proy!$D$13 -> 548702
A14: Ibagué | B14: 2026 | C14: 59.7518 | D14: 57.2694 | E14: 62.3418 | F14: =E14-D14 -> 5.0724 | G14: =Ocupados_Proy!$D$14 -> 378451
A15: Montería | B15: 2026 | C15: 73.328 | D15: 70.6106 | E15: 76.1501 | F15: =E15-D15 -> 5.5395 | G15: =Ocupados_Proy!$D$15 -> 390914
A16: Cartagena | B16: 2026 | C16: 55.1 | D16: 52.613 | E16: 57.7045 | F16: =E16-D16 -> 5.0915 | G16: =Ocupados_Proy!$D$16 -> 673241
A17: Villavicencio | B17: 2026 | C17: 60.3126 | D17: 57.7552 | E17: 62.9832 | F17: =E17-D17 -> 5.228 | G17: =Ocupados_Proy!$D$17 -> 409780
A18: Tunja | B18: 2026 | C18: 60.1797 | D18: 57.7241 | E18: 62.7398 | F18: =E18-D18 -> 5.0157 | G18: =Ocupados_Proy!$D$18 -> 136338
A19: Florencia | B19: 2026 | C19: 74.5564 | D19: 71.9401 | E19: 77.2679 | F19: =E19-D19 -> 5.3278 | G19: =Ocupados_Proy!$D$19 -> 129659
A20: Popayán | B20: 2026 | C20: 68.081 | D20: 65.5656 | E20: 70.6929 | F20: =E20-D20 -> 5.1273 | G20: =Ocupados_Proy!$D$20 -> 248848
A21: Valledupar | B21: 2026 | C21: 66.6179 | D21: 64.0477 | E21: 69.2913 | F21: =E21-D21 -> 5.2436 | G21: =Ocupados_Proy!$D$21 -> 421498
A22: Quibdó | B22: 2026 | C22: 77.5699 | D22: 74.9559 | E22: 80.2751 | F22: =E22-D22 -> 5.3192 | G22: =Ocupados_Proy!$D$22 -> 95484
A23: Neiva | B23: 2026 | C23: 64.0151 | D23: 61.4889 | E23: 66.645 | F23: =E23-D23 -> 5.1561 | G23: =Ocupados_Proy!$D$23 -> 276241
A24: Riohacha | B24: 2026 | C24: 72.3136 | D24: 69.73 | E24: 74.9928 | F24: =E24-D24 -> 5.2628 | G24: =Ocupados_Proy!$D$24 -> 137916
A25: Santa Marta | B25: 2026 | C25: 57.7023 | D25: 55.179 | E25: 60.3411 | F25: =E25-D25 -> 5.1621 | G25: =Ocupados_Proy!$D$25 -> 402356
A26: Armenia | B26: 2026 | C26: 53.9082 | D26: 51.3628 | E26: 56.5798 | F26: =E26-D26 -> 5.217 | G26: =Ocupados_Proy!$D$26 -> 208250
A27: Sincelejo | B27: 2026 | C27: 67.2907 | D27: 64.7057 | E27: 69.9789 | F27: =E27-D27 -> 5.2732 | G27: =Ocupados_Proy!$D$27 -> 221871
A28: Bogotá D.C. | B28: 2027 | C28: 41.072 | D28: 38.0294 | E28: 44.3579 | F28: =E28-D28 -> 6.3285 | G28: =Ocupados_Proy!$D$28 -> 5690929
A29: Medellín | B29: 2027 | C29: 41.2616 | D29: 37.4361 | E29: 45.4781 | F29: =E29-D29 -> 8.042 | G29: =Ocupados_Proy!$D$29 -> 1766956
A30: Cali | B30: 2027 | C30: 48.4327 | D30: 44.8362 | E30: 52.3177 | F30: =E30-D30 -> 7.4815 | G30: =Ocupados_Proy!$D$30 -> 1568387
A31: Barranquilla | B31: 2027 | C31: 54.8516 | D31: 51.7158 | E31: 58.1776 | F31: =E31-D31 -> 6.4618 | G31: =Ocupados_Proy!$D$31 -> 861851
A32: Bucaramanga | B32: 2027 | C32: 60.6248 | D32: 56.77 | E32: 64.7414 | F32: =E32-D32 -> 7.9714 | G32: =Ocupados_Proy!$D$32 -> 424405
A33: Manizales | B33: 2027 | C33: 48.2274 | D33: 44.7405 | E33: 51.9861 | F33: =E33-D33 -> 7.2456 | G33: =Ocupados_Proy!$D$33 -> 330248
A34: Pasto | B34: 2027 | C34: 67.5826 | D34: 64.7655 | E34: 70.5223 | F34: =E34-D34 -> 5.7568 | G34: =Ocupados_Proy!$D$34 -> 289337
A35: Pereira | B35: 2027 | C35: 56.1586 | D35: 52.8525 | E35: 59.6715 | F35: =E35-D35 -> 6.819 | G35: =Ocupados_Proy!$D$35 -> 331418
A36: Cúcuta | B36: 2027 | C36: 68.645 | D36: 64.9084 | E36: 72.5968 | F36: =E36-D36 -> 7.6884 | G36: =Ocupados_Proy!$D$36 -> 548829
A37: Ibagué | B37: 2027 | C37: 59.4373 | D37: 56.4273 | E37: 62.6079 | F37: =E37-D37 -> 6.1806 | G37: =Ocupados_Proy!$D$37 -> 379844
A38: Montería | B38: 2027 | C38: 72.9845 | D38: 69.6858 | E38: 76.4394 | F38: =E38-D38 -> 6.7536 | G38: =Ocupados_Proy!$D$38 -> 398865
A39: Cartagena | B39: 2027 | C39: 54.7844 | D39: 51.7715 | E39: 57.9727 | F39: =E39-D39 -> 6.2012 | G39: =Ocupados_Proy!$D$39 -> 673082
A40: Villavicencio | B40: 2027 | C40: 59.9885 | D40: 56.8883 | E40: 63.2577 | F40: =E40-D40 -> 6.3694 | G40: =Ocupados_Proy!$D$40 -> 413292
A41: Tunja | B41: 2027 | C41: 59.8688 | D41: 56.8907 | E41: 63.0028 | F41: =E41-D41 -> 6.1121 | G41: =Ocupados_Proy!$D$41 -> 137750
A42: Florencia | B42: 2027 | C42: 74.226 | D42: 71.0486 | E42: 77.5455 | F42: =E42-D42 -> 6.4969 | G42: =Ocupados_Proy!$D$42 -> 131492
...

Sheet Ocupados_Proy
A1: OCUPADOS INFORMALES Y FORMALES PROYECTADOS | PEA 15-64 AÑOS | 2026–2042
A3: NOTA METODOLÓGICA: Los valores de ocupados informales y formales proyectados se estiman aplicando la tasa de informalidad sobre la PEA de 15 a 64 años, utilizada como proxy del universo laboral disponible. Por tanto, estas cifras no corresponden a conteos directos de ocupados efectivos, sino a estimaciones aproximadas para fines comparativos y prospectivos.
A4: Ciudad | B4: Año | C4: Población Total | D4: PEA 15-64 | E4: Tasa Informalidad (%) | F4: Ocupados Informales | G4: Ocupados Formales | H4: Var. Tasa vs 2018 (pp) | I4: Part. PEA/PobTotal (%) | J4: Dependencia (%)
A5: Bogotá D.C. | B5: 2026 | C5: 7945996 | D5: 5694816 | E5: =Tasas_Informalidad_Proy!$B$6 -> 41.3942 | F5: =D5*E5/100 -> 2357323.5 | G5: =D5*(1-E5/100) -> 3337492.5 | H5: =E5-'Historico_GEIH_2007-2026'!$M$6 -> -1.2058 | I5: =IF(C5>0,D5/C5*100,"") -> 71.669002 | J5: =IF(D5>0,(C5-D5)/D5*100,"") -> 39.530338
A6: Medellín | B6: 2026 | C6: 2526795 | D6: 1772378 | E6: =Tasas_Informalidad_Proy!$B$7 -> 41.6713 | F6: =D6*E6/100 -> 738572.95 | G6: =D6*(1-E6/100) -> 1033805 | H6: =E6-'Historico_GEIH_2007-2026'!$M$7 -> -1.5287 | I6: =IF(C6>0,D6/C6*100,"") -> 70.143324 | J6: =IF(D6>0,(C6-D6)/D6*100,"") -> 42.565243
A7: Cali | B7: 2026 | C7: 2269983 | D7: 1576113 | E7: =Tasas_Informalidad_Proy!$B$8 -> 48.8136 | F7: =D7*E7/100 -> 769357.5 | G7: =D7*(1-E7/100) -> 806755.5 | H7: =E7-'Historico_GEIH_2007-2026'!$M$8 -> -1.4864 | I7: =IF(C7>0,D7/C7*100,"") -> 69.432811 | J7: =IF(D7>0,(C7-D7)/D7*100,"") -> 44.024128
A8: Barranquilla | B8: 2026 | C8: 1275854 | D8: 864371 | E8: =Tasas_Informalidad_Proy!$B$9 -> 55.1804 | F8: =D8*E8/100 -> 476963.38 | G8: =D8*(1-E8/100) -> 387407.62 | H8: =E8-'Historico_GEIH_2007-2026'!$M$9 -> -1.0196 | I8: =IF(C8>0,D8/C8*100,"") -> 67.748426 | J8: =IF(D8>0,(C8-D8)/D8*100,"") -> 47.604906
A9: Bucaramanga | B9: 2026 | C9: 618548 | D9: 424315 | E9: =Tasas_Informalidad_Proy!$B$10 -> 61.0305 | F9: =D9*E9/100 -> 258961.57 | G9: =D9*(1-E9/100) -> 165353.43 | H9: =E9-'Historico_GEIH_2007-2026'!$M$10 -> -1.3695 | I9: =IF(C9>0,D9/C9*100,"") -> 68.598557 | J9: =IF(D9>0,(C9-D9)/D9*100,"") -> 45.775662
A10: Manizales | B10: 2026 | C10: 475690 | D10: 328451 | E10: =Tasas_Informalidad_Proy!$B$11 -> 48.5963 | F10: =D10*E10/100 -> 159615.03 | G10: =D10*(1-E10/100) -> 168835.97 | H10: =E10-'Historico_GEIH_2007-2026'!$M$11 -> -1.3037 | I10: =IF(C10>0,D10/C10*100,"") -> 69.047279 | J10: =IF(D10>0,(C10-D10)/D10*100,"") -> 44.8283
A11: Pasto | B11: 2026 | C11: 404775 | D11: 288315 | E11: =Tasas_Informalidad_Proy!$B$12 -> 67.8754 | F11: =D11*E11/100 -> 195694.96 | G11: =D11*(1-E11/100) -> 92620.04 | H11: =E11-'Historico_GEIH_2007-2026'!$M$12 -> -1.0246 | I11: =IF(C11>0,D11/C11*100,"") -> 71.22846 | J11: =IF(D11>0,(C11-D11)/D11*100,"") -> 40.39332
A12: Pereira | B12: 2026 | C12: 487820 | D12: 331654 | E12: =Tasas_Informalidad_Proy!$B$13 -> 56.5056 | F12: =D12*E12/100 -> 187403.08 | G12: =D12*(1-E12/100) -> 144250.92 | H12: =E12-'Historico_GEIH_2007-2026'!$M$13 -> -0.9944 | I12: =IF(C12>0,D12/C12*100,"") -> 67.986962 | J12: =IF(D12>0,(C12-D12)/D12*100,"") -> 47.087024
A13: Cúcuta | B13: 2026 | C13: 792180 | D13: 548702 | E13: =Tasas_Informalidad_Proy!$B$14 -> 69.0362 | F13: =D13*E13/100 -> 378803.01 | G13: =D13*(1-E13/100) -> 169898.99 | H13: =E13-'Historico_GEIH_2007-2026'!$M$14 -> -1.2638 | I13: =IF(C13>0,D13/C13*100,"") -> 69.264814 | J13: =IF(D13>0,(C13-D13)/D13*100,"") -> 44.373449
A14: Ibagué | B14: 2026 | C14: 557317 | D14: 378451 | E14: =Tasas_Informalidad_Proy!$B$15 -> 59.7518 | F14: =D14*E14/100 -> 226131.28 | G14: =D14*(1-E14/100) -> 152319.72 | H14: =E14-'Historico_GEIH_2007-2026'!$M$15 -> -0.7482 | I14: =IF(C14>0,D14/C14*100,"") -> 67.905878 | J14: =IF(D14>0,(C14-D14)/D14*100,"") -> 47.262658
A15: Montería | B15: 2026 | C15: 585029 | D15: 390914 | E15: =Tasas_Informalidad_Proy!$B$16 -> 73.328 | F15: =D15*E15/100 -> 286649.42 | G15: =D15*(1-E15/100) -> 104264.58 | H15: =E15-'Historico_GEIH_2007-2026'!$M$16 -> -1.072 | I15: =IF(C15>0,D15/C15*100,"") -> 66.819594 | J15: =IF(D15>0,(C15-D15)/D15*100,"") -> 49.656702
A16: Cartagena | B16: 2026 | C16: 1010995 | D16: 673241 | E16: =Tasas_Informalidad_Proy!$B$17 -> 55.1 | F16: =D16*E16/100 -> 370955.79 | G16: =D16*(1-E16/100) -> 302285.21 | H16: =E16-'Historico_GEIH_2007-2026'!$M$17 -> -1 | I16: =IF(C16>0,D16/C16*100,"") -> 66.591922 | J16: =IF(D16>0,(C16-D16)/D16*100,"") -> 50.168365
A17: Villavicencio | B17: 2026 | C17: 588645 | D17: 409780 | E17: =Tasas_Informalidad_Proy!$B$18 -> 60.3126 | F17: =D17*E17/100 -> 247148.97 | G17: =D17*(1-E17/100) -> 162631.03 | H17: =E17-'Historico_GEIH_2007-2026'!$M$18 -> -0.9874 | I17: =IF(C17>0,D17/C17*100,"") -> 69.614114 | J17: =IF(D17>0,(C17-D17)/D17*100,"") -> 43.649031
A18: Tunja | B18: 2026 | C18: 191372 | D18: 136338 | E18: =Tasas_Informalidad_Proy!$B$19 -> 60.1797 | F18: =D18*E18/100 -> 82047.799 | G18: =D18*(1-E18/100) -> 54290.201 | H18: =E18-'Historico_GEIH_2007-2026'!$M$19 -> -1.0203 | I18: =IF(C18>0,D18/C18*100,"") -> 71.242397 | J18: =IF(D18>0,(C18-D18)/D18*100,"") -> 40.365855
A19: Florencia | B19: 2026 | C19: 188620 | D19: 129659 | E19: =Tasas_Informalidad_Proy!$B$20 -> 74.5564 | F19: =D19*E19/100 -> 96669.083 | G19: =D19*(1-E19/100) -> 32989.917 | H19: =E19-'Historico_GEIH_2007-2026'!$M$20 -> -0.9436 | I19: =IF(C19>0,D19/C19*100,"") -> 68.740855 | J19: =IF(D19>0,(C19-D19)/D19*100,"") -> 45.473897
A20: Popayán | B20: 2026 | C20: 355347 | D20: 248848 | E20: =Tasas_Informalidad_Proy!$B$21 -> 68.081 | F20: =D20*E20/100 -> 169418.21 | G20: =D20*(1-E20/100) -> 79429.793 | H20: =E20-'Historico_GEIH_2007-2026'!$M$21 -> -0.919 | I20: =IF(C20>0,D20/C20*100,"") -> 70.029577 | J20: =IF(D20>0,(C20-D20)/D20*100,"") -> 42.796808
A21: Valledupar | B21: 2026 | C21: 629217 | D21: 421498 | E21: =Tasas_Informalidad_Proy!$B$22 -> 66.6179 | F21: =D21*E21/100 -> 280793.12 | G21: =D21*(1-E21/100) -> 140704.88 | H21: =E21-'Historico_GEIH_2007-2026'!$M$22 -> -0.9821 | I21: =IF(C21>0,D21/C21*100,"") -> 66.987701 | J21: =IF(D21>0,(C21-D21)/D21*100,"") -> 49.281135
A22: Quibdó | B22: 2026 | C22: 143332 | D22: 95484 | E22: =Tasas_Informalidad_Proy!$B$23 -> 77.5699 | F22: =D22*E22/100 -> 74066.843 | G22: =D22*(1-E22/100) -> 21417.157 | H22: =E22-'Historico_GEIH_2007-2026'!$M$23 -> -0.9301 | I22: =IF(C22>0,D22/C22*100,"") -> 66.617364 | J22: =IF(D22>0,(C22-D22)/D22*100,"") -> 50.111013
A23: Neiva | B23: 2026 | C23: 408218 | D23: 276241 | E23: =Tasas_Informalidad_Proy!$B$24 -> 64.0151 | F23: =D23*E23/100 -> 176835.95 | G23: =D23*(1-E23/100) -> 99405.048 | H23: =E23-'Historico_GEIH_2007-2026'!$M$24 -> -0.9849 | I23: =IF(C23>0,D23/C23*100,"") -> 67.66997 | J23: =IF(D23>0,(C23-D23)/D23*100,"") -> 47.776036
A24: Riohacha | B24: 2026 | C24: 211811 | D24: 137916 | E24: =Tasas_Informalidad_Proy!$B$25 -> 72.3136 | F24: =D24*E24/100 -> 99732.025 | G24: =D24*(1-E24/100) -> 38183.975 | H24: =E24-'Historico_GEIH_2007-2026'!$M$25 -> -0.9864 | I24: =IF(C24>0,D24/C24*100,"") -> 65.112766 | J24: =IF(D24>0,(C24-D24)/D24*100,"") -> 53.579715
A25: Santa Marta | B25: 2026 | C25: 588662 | D25: 402356 | E25: =Tasas_Informalidad_Proy!$B$26 -> 57.7023 | F25: =D25*E25/100 -> 232168.67 | G25: =D25*(1-E25/100) -> 170187.33 | H25: =E25-'Historico_GEIH_2007-2026'!$M$26 -> -0.9977 | I25: =IF(C25>0,D25/C25*100,"") -> 68.350938 | J25: =IF(D25>0,(C25-D25)/D25*100,"") -> 46.303771
A26: Armenia | B26: 2026 | C26: 307103 | D26: 208250 | E26: =Tasas_Informalidad_Proy!$B$27 -> 53.9082 | F26: =D26*E26/100 -> 112263.83 | G26: =D26*(1-E26/100) -> 95986.173 | H26: =E26-'Historico_GEIH_2007-2026'!$M$27 -> -1.0918 | I26: =IF(C26>0,D26/C26*100,"") -> 67.811125 | J26: =IF(D26>0,(C26-D26)/D26*100,"") -> 47.468427
A27: Sincelejo | B27: 2026 | C27: 331045 | D27: 221871 | E27: =Tasas_Informalidad_Proy!$B$28 -> 67.2907 | F27: =D27*E27/100 -> 149298.55 | G27: =D27*(1-E27/100) -> 72572.451 | H27: =E27-'Historico_GEIH_2007-2026'!$M$28 -> -1.0093 | I27: =IF(C27>0,D27/C27*100,"") -> 67.021402 | J27: =IF(D27>0,(C27-D27)/D27*100,"") -> 49.20607
A28: Bogotá D.C. | B28: 2027 | C28: 7943941 | D28: 5690929 | E28: =Tasas_Informalidad_Proy!$C$6 -> 41.072 | F28: =D28*E28/100 -> 2337378.4 | G28: =D28*(1-E28/100) -> 3353550.6 | H28: =E28-'Historico_GEIH_2007-2026'!$M$6 -> -1.528 | I28: =IF(C28>0,D28/C28*100,"") -> 71.638611 | J28: =IF(D28>0,(C28-D28)/D28*100,"") -> 39.589529
A29: Medellín | B29: 2027 | C29: 2524037 | D29: 1766956 | E29: =Tasas_Informalidad_Proy!$C$7 -> 41.2616 | F29: =D29*E29/100 -> 729074.32 | G29: =D29*(1-E29/100) -> 1037881.7 | H29: =E29-'Historico_GEIH_2007-2026'!$M$7 -> -1.9384 | I29: =IF(C29>0,D29/C29*100,"") -> 70.005154 | J29: =IF(D29>0,(C29-D29)/D29*100,"") -> 42.846624
A30: Cali | B30: 2027 | C30: 2261787 | D30: 1568387 | E30: =Tasas_Informalidad_Proy!$C$8 -> 48.4327 | F30: =D30*E30/100 -> 759612.17 | G30: =D30*(1-E30/100) -> 808774.83 | H30: =E30-'Historico_GEIH_2007-2026'!$M$8 -> -1.8673 | I30: =IF(C30>0,D30/C30*100,"") -> 69.342825 | J30: =IF(D30>0,(C30-D30)/D30*100,"") -> 44.211027
A31: Barranquilla | B31: 2027 | C31: 1271416 | D31: 861851 | E31: =Tasas_Informalidad_Proy!$C$9 -> 54.8516 | F31: =D31*E31/100 -> 472739.06 | G31: =D31*(1-E31/100) -> 389111.94 | H31: =E31-'Historico_GEIH_2007-2026'!$M$9 -> -1.3484 | I31: =IF(C31>0,D31/C31*100,"") -> 67.786704 | J31: =IF(D31>0,(C31-D31)/D31*100,"") -> 47.521555
A32: Bucaramanga | B32: 2027 | C32: 619155 | D32: 424405 | E32: =Tasas_Informalidad_Proy!$C$10 -> 60.6248 | F32: =D32*E32/100 -> 257294.68 | G32: =D32*(1-E32/100) -> 167110.32 | H32: =E32-'Historico_GEIH_2007-2026'!$M$10 -> -1.7752 | I32: =IF(C32>0,D32/C32*100,"") -> 68.545841 | J32: =IF(D32>0,(C32-D32)/D32*100,"") -> 45.887772
A33: Manizales | B33: 2027 | C33: 479109 | D33: 330248 | E33: =Tasas_Informalidad_Proy!$C$11 -> 48.2274 | F33: =D33*E33/100 -> 159270.02 | G33: =D33*(1-E33/100) -> 170977.98 | H33: =E33-'Historico_GEIH_2007-2026'!$M$11 -> -1.6726 | I33: =IF(C33>0,D33/C33*100,"") -> 68.929617 | J33: =IF(D33>0,(C33-D33)/D33*100,"") -> 45.075519
A34: Pasto | B34: 2027 | C34: 405306 | D34: 289337 | E34: =Tasas_Informalidad_Proy!$C$12 -> 67.5826 | F34: =D34*E34/100 -> 195541.47 | G34: =D34*(1-E34/100) -> 93795.533 | H34: =E34-'Historico_GEIH_2007-2026'!$M$12 -> -1.3174 | I34: =IF(C34>0,D34/C34*100,"") -> 71.387297 | J34: =IF(D34>0,(C34-D34)/D34*100,"") -> 40.080944
A35: Pereira | B35: 2027 | C35: 488044 | D35: 331418 | E35: =Tasas_Informalidad_Proy!$C$13 -> 56.1586 | F35: =D35*E35/100 -> 186119.71 | G35: =D35*(1-E35/100) -> 145298.29 | H35: =E35-'Historico_GEIH_2007-2026'!$M$13 -> -1.3414 | I35: =IF(C35>0,D35/C35*100,"") -> 67.907402 | J35: =IF(D35>0,(C35-D35)/D35*100,"") -> 47.259352
A36: Cúcuta | B36: 2027 | C36: 790552 | D36: 548829 | E36: =Tasas_Informalidad_Proy!$C$14 -> 68.645 | F36: =D36*E36/100 -> 376743.67 | G36: =D36*(1-E36/100) -> 172085.33 | H36: =E36-'Historico_GEIH_2007-2026'!$M$14 -> -1.655 | I36: =IF(C36>0,D36/C36*100,"") -> 69.423517 | J36: =IF(D36>0,(C36-D36)/D36*100,"") -> 44.043409
A37: Ibagué | B37: 2027 | C37: 559515 | D37: 379844 | E37: =Tasas_Informalidad_Proy!$C$15 -> 59.4373 | F37: =D37*E37/100 -> 225769.02 | G37: =D37*(1-E37/100) -> 154074.98 | H37: =E37-'Historico_GEIH_2007-2026'!$M$15 -> -1.0627 | I37: =IF(C37>0,D37/C37*100,"") -> 67.888082 | J37: =IF(D37>0,(C37-D37)/D37*100,"") -> 47.301261
A38: Montería | B38: 2027 | C38: 595299 | D38: 398865 | E38: =Tasas_Informalidad_Proy!$C$16 -> 72.9845 | F38: =D38*E38/100 -> 291109.63 | G38: =D38*(1-E38/100) -> 107755.37 | H38: =E38-'Historico_GEIH_2007-2026'!$M$16 -> -1.4155 | I38: =IF(C38>0,D38/C38*100,"") -> 67.002464 | J38: =IF(D38>0,(C38-D38)/D38*100,"") -> 49.248242
A39: Cartagena | B39: 2027 | C39: 1010001 | D39: 673082 | E39: =Tasas_Informalidad_Proy!$C$17 -> 54.7844 | F39: =D39*E39/100 -> 368743.94 | G39: =D39*(1-E39/100) -> 304338.06 | H39: =E39-'Historico_GEIH_2007-2026'!$M$17 -> -1.3156 | I39: =IF(C39>0,D39/C39*100,"") -> 66.641716 | J39: =IF(D39>0,(C39-D39)/D39*100,"") -> 50.05616
A40: Villavicencio | B40: 2027 | C40: 592656 | D40: 413292 | E40: =Tasas_Informalidad_Proy!$C$18 -> 59.9885 | F40: =D40*E40/100 -> 247927.67 | G40: =D40*(1-E40/100) -> 165364.33 | H40: =E40-'Historico_GEIH_2007-2026'!$M$18 -> -1.3115 | I40: =IF(C40>0,D40/C40*100,"") -> 69.735563 | J40: =IF(D40>0,(C40-D40)/D40*100,"") -> 43.398856
A41: Tunja | B41: 2027 | C41: 193090 | D41: 137750 | E41: =Tasas_Informalidad_Proy!$C$19 -> 59.8688 | F41: =D41*E41/100 -> 82469.272 | G41: =D41*(1-E41/100) -> 55280.728 | H41: =E41-'Historico_GEIH_2007-2026'!$M$19 -> -1.3312 | I41: =IF(C41>0,D41/C41*100,"") -> 71.33979 | J41: =IF(D41>0,(C41-D41)/D41*100,"") -> 40.174229
...

Sheet Resumen_por_Año
A1: RESUMEN ANUAL — INFORMALIDAD NACIONAL | 2026–2042 | Fórmulas sobre Ocupados_Proy
A3: Nota: El total de informales estimados se calcula sobre la PEA 15-64 como proxy de ocupados; por ello, debe interpretarse como una estimación aproximada y no como conteo directo de ocupados efectivos..
A4: Año | B4: Promedio Ponderado (%) | C4: Mínimo (%) | D4: Máximo (%) | E4: Rango (pp) | F4: Ciudad con Menor Informalidad | G4: Ciudad con Mayor Informalidad | H4: Total Informales Estimados
A5: 2026 | B5: =SUMPRODUCT(Ocupados_Proy!$E$5:$E$27,Ocupados_Proy!$D$5:$D$27)/SUM(Ocupados_Proy!$D$5:$D$27) -> 50.920388 | C5: =MIN(Ocupados_Proy!$E$5:$E$27) -> 41.3942 | D5: =MAX(Ocupados_Proy!$E$5:$E$27) -> 77.5699 | E5: =D5-C5 -> 36.1757 | F5: =INDEX(Ocupados_Proy!$A$5:$A$27,MATCH(C5,Ocupados_Proy!$E$5:$E$27,0)) -> Bogotá D.C. | G5: =INDEX(Ocupados_Proy!$A$5:$A$27,MATCH(D5,Ocupados_Proy!$E$5:$E$27,0)) -> Quibdó | H5: =SUM(Ocupados_Proy!$F$5:$F$27) -> 8126874.5
A6: 2027 | B6: =SUMPRODUCT(Ocupados_Proy!$E$28:$E$50,Ocupados_Proy!$D$28:$D$50)/SUM(Ocupados_Proy!$D$28:$D$50) -> 50.629067 | C6: =MIN(Ocupados_Proy!$E$28:$E$50) -> 41.072 | D6: =MAX(Ocupados_Proy!$E$28:$E$50) -> 77.24 | E6: =D6-C6 -> 36.168 | F6: =INDEX(Ocupados_Proy!$A$28:$A$50,MATCH(C6,Ocupados_Proy!$E$28:$E$50,0)) -> Bogotá D.C. | G6: =INDEX(Ocupados_Proy!$A$28:$A$50,MATCH(D6,Ocupados_Proy!$E$28:$E$50,0)) -> Quibdó | H6: =SUM(Ocupados_Proy!$F$28:$F$50) -> 8095469.8
A7: 2028 | B7: =SUMPRODUCT(Ocupados_Proy!$E$51:$E$73,Ocupados_Proy!$D$51:$D$73)/SUM(Ocupados_Proy!$D$51:$D$73) -> 50.341094 | C7: =MIN(Ocupados_Proy!$E$51:$E$73) -> 40.7523 | D7: =MAX(Ocupados_Proy!$E$51:$E$73) -> 76.9114 | E7: =D7-C7 -> 36.1591 | F7: =INDEX(Ocupados_Proy!$A$51:$A$73,MATCH(C7,Ocupados_Proy!$E$51:$E$73,0)) -> Bogotá D.C. | G7: =INDEX(Ocupados_Proy!$A$51:$A$73,MATCH(D7,Ocupados_Proy!$E$51:$E$73,0)) -> Quibdó | H7: =SUM(Ocupados_Proy!$F$51:$F$73) -> 8058784.1
A8: 2029 | B8: =SUMPRODUCT(Ocupados_Proy!$E$74:$E$96,Ocupados_Proy!$D$74:$D$96)/SUM(Ocupados_Proy!$D$74:$D$96) -> 50.056273 | C8: =MIN(Ocupados_Proy!$E$74:$E$96) -> 40.4351 | D8: =MAX(Ocupados_Proy!$E$74:$E$96) -> 76.5843 | E8: =D8-C8 -> 36.1492 | F8: =INDEX(Ocupados_Proy!$A$74:$A$96,MATCH(C8,Ocupados_Proy!$E$74:$E$96,0)) -> Bogotá D.C. | G8: =INDEX(Ocupados_Proy!$A$74:$A$96,MATCH(D8,Ocupados_Proy!$E$74:$E$96,0)) -> Quibdó | H8: =SUM(Ocupados_Proy!$F$74:$F$96) -> 8018350.8
A9: 2030 | B9: =SUMPRODUCT(Ocupados_Proy!$E$97:$E$119,Ocupados_Proy!$D$97:$D$119)/SUM(Ocupados_Proy!$D$97:$D$119) -> 49.774479 | C9: =MIN(Ocupados_Proy!$E$97:$E$119) -> 40.0568 | D9: =MAX(Ocupados_Proy!$E$97:$E$119) -> 76.2585 | E9: =D9-C9 -> 36.2017 | F9: =INDEX(Ocupados_Proy!$A$97:$A$119,MATCH(C9,Ocupados_Proy!$E$97:$E$119,0)) -> Medellín | G9: =INDEX(Ocupados_Proy!$A$97:$A$119,MATCH(D9,Ocupados_Proy!$E$97:$E$119,0)) -> Quibdó | H9: =SUM(Ocupados_Proy!$F$97:$F$119) -> 7975370.8
A10: 2031 | B10: =SUMPRODUCT(Ocupados_Proy!$E$120:$E$142,Ocupados_Proy!$D$120:$D$142)/SUM(Ocupados_Proy!$D$120:$D$142) -> 49.495511 | C10: =MIN(Ocupados_Proy!$E$120:$E$142) -> 39.6631 | D10: =MAX(Ocupados_Proy!$E$120:$E$142) -> 75.9342 | E10: =D10-C10 -> 36.2711 | F10: =INDEX(Ocupados_Proy!$A$120:$A$142,MATCH(C10,Ocupados_Proy!$E$120:$E$142,0)) -> Medellín | G10: =INDEX(Ocupados_Proy!$A$120:$A$142,MATCH(D10,Ocupados_Proy!$E$120:$E$142,0)) -> Quibdó | H10: =SUM(Ocupados_Proy!$F$120:$F$142) -> 7930211.4
A11: 2032 | B11: =SUMPRODUCT(Ocupados_Proy!$E$143:$E$165,Ocupados_Proy!$D$143:$D$165)/SUM(Ocupados_Proy!$D$143:$D$165) -> 49.219419 | C11: =MIN(Ocupados_Proy!$E$143:$E$165) -> 39.2732 | D11: =MAX(Ocupados_Proy!$E$143:$E$165) -> 75.6112 | E11: =D11-C11 -> 36.338 | F11: =INDEX(Ocupados_Proy!$A$143:$A$165,MATCH(C11,Ocupados_Proy!$E$143:$E$165,0)) -> Medellín | G11: =INDEX(Ocupados_Proy!$A$143:$A$165,MATCH(D11,Ocupados_Proy!$E$143:$E$165,0)) -> Quibdó | H11: =SUM(Ocupados_Proy!$F$143:$F$165) -> 7883378.8
A12: 2033 | B12: =SUMPRODUCT(Ocupados_Proy!$E$166:$E$188,Ocupados_Proy!$D$166:$D$188)/SUM(Ocupados_Proy!$D$166:$D$188) -> 48.945838 | C12: =MIN(Ocupados_Proy!$E$166:$E$188) -> 38.8871 | D12: =MAX(Ocupados_Proy!$E$166:$E$188) -> 75.2896 | E12: =D12-C12 -> 36.4025 | F12: =INDEX(Ocupados_Proy!$A$166:$A$188,MATCH(C12,Ocupados_Proy!$E$166:$E$188,0)) -> Medellín | G12: =INDEX(Ocupados_Proy!$A$166:$A$188,MATCH(D12,Ocupados_Proy!$E$166:$E$188,0)) -> Quibdó | H12: =SUM(Ocupados_Proy!$F$166:$F$188) -> 7834945.9
A13: 2034 | B13: =SUMPRODUCT(Ocupados_Proy!$E$189:$E$211,Ocupados_Proy!$D$189:$D$211)/SUM(Ocupados_Proy!$D$189:$D$211) -> 48.675116 | C13: =MIN(Ocupados_Proy!$E$189:$E$211) -> 38.5049 | D13: =MAX(Ocupados_Proy!$E$189:$E$211) -> 74.9694 | E13: =D13-C13 -> 36.4645 | F13: =INDEX(Ocupados_Proy!$A$189:$A$211,MATCH(C13,Ocupados_Proy!$E$189:$E$211,0)) -> Medellín | G13: =INDEX(Ocupados_Proy!$A$189:$A$211,MATCH(D13,Ocupados_Proy!$E$189:$E$211,0)) -> Quibdó | H13: =SUM(Ocupados_Proy!$F$189:$F$211) -> 7784071.9
A14: 2035 | B14: =SUMPRODUCT(Ocupados_Proy!$E$212:$E$234,Ocupados_Proy!$D$212:$D$234)/SUM(Ocupados_Proy!$D$212:$D$234) -> 48.406669 | C14: =MIN(Ocupados_Proy!$E$212:$E$234) -> 38.1264 | D14: =MAX(Ocupados_Proy!$E$212:$E$234) -> 74.6505 | E14: =D14-C14 -> 36.5241 | F14: =INDEX(Ocupados_Proy!$A$212:$A$234,MATCH(C14,Ocupados_Proy!$E$212:$E$234,0)) -> Medellín | G14: =INDEX(Ocupados_Proy!$A$212:$A$234,MATCH(D14,Ocupados_Proy!$E$212:$E$234,0)) -> Quibdó | H14: =SUM(Ocupados_Proy!$F$212:$F$234) -> 7732432
A15: 2036 | B15: =SUMPRODUCT(Ocupados_Proy!$E$235:$E$257,Ocupados_Proy!$D$235:$D$257)/SUM(Ocupados_Proy!$D$235:$D$257) -> 48.141651 | C15: =MIN(Ocupados_Proy!$E$235:$E$257) -> 37.7516 | D15: =MAX(Ocupados_Proy!$E$235:$E$257) -> 74.333 | E15: =D15-C15 -> 36.5814 | F15: =INDEX(Ocupados_Proy!$A$235:$A$257,MATCH(C15,Ocupados_Proy!$E$235:$E$257,0)) -> Medellín | G15: =INDEX(Ocupados_Proy!$A$235:$A$257,MATCH(D15,Ocupados_Proy!$E$235:$E$257,0)) -> Quibdó | H15: =SUM(Ocupados_Proy!$F$235:$F$257) -> 7681033.2
A16: 2037 | B16: =SUMPRODUCT(Ocupados_Proy!$E$258:$E$280,Ocupados_Proy!$D$258:$D$280)/SUM(Ocupados_Proy!$D$258:$D$280) -> 47.879272 | C16: =MIN(Ocupados_Proy!$E$258:$E$280) -> 37.3805 | D16: =MAX(Ocupados_Proy!$E$258:$E$280) -> 74.0168 | E16: =D16-C16 -> 36.6363 | F16: =INDEX(Ocupados_Proy!$A$258:$A$280,MATCH(C16,Ocupados_Proy!$E$258:$E$280,0)) -> Medellín | G16: =INDEX(Ocupados_Proy!$A$258:$A$280,MATCH(D16,Ocupados_Proy!$E$258:$E$280,0)) -> Quibdó | H16: =SUM(Ocupados_Proy!$F$258:$F$280) -> 7628272.5
A17: 2038 | B17: =SUMPRODUCT(Ocupados_Proy!$E$281:$E$303,Ocupados_Proy!$D$281:$D$303)/SUM(Ocupados_Proy!$D$281:$D$303) -> 47.61969 | C17: =MIN(Ocupados_Proy!$E$281:$E$303) -> 37.0131 | D17: =MAX(Ocupados_Proy!$E$281:$E$303) -> 73.702 | E17: =D17-C17 -> 36.6889 | F17: =INDEX(Ocupados_Proy!$A$281:$A$303,MATCH(C17,Ocupados_Proy!$E$281:$E$303,0)) -> Medellín | G17: =INDEX(Ocupados_Proy!$A$281:$A$303,MATCH(D17,Ocupados_Proy!$E$281:$E$303,0)) -> Quibdó | H17: =SUM(Ocupados_Proy!$F$281:$F$303) -> 7573911.2
A18: 2039 | B18: =SUMPRODUCT(Ocupados_Proy!$E$304:$E$326,Ocupados_Proy!$D$304:$D$326)/SUM(Ocupados_Proy!$D$304:$D$326) -> 47.363259 | C18: =MIN(Ocupados_Proy!$E$304:$E$326) -> 36.6493 | D18: =MAX(Ocupados_Proy!$E$304:$E$326) -> 73.3885 | E18: =D18-C18 -> 36.7392 | F18: =INDEX(Ocupados_Proy!$A$304:$A$326,MATCH(C18,Ocupados_Proy!$E$304:$E$326,0)) -> Medellín | G18: =INDEX(Ocupados_Proy!$A$304:$A$326,MATCH(D18,Ocupados_Proy!$E$304:$E$326,0)) -> Quibdó | H18: =SUM(Ocupados_Proy!$F$304:$F$326) -> 7517512.5
A19: 2040 | B19: =SUMPRODUCT(Ocupados_Proy!$E$327:$E$349,Ocupados_Proy!$D$327:$D$349)/SUM(Ocupados_Proy!$D$327:$D$349) -> 47.110067 | C19: =MIN(Ocupados_Proy!$E$327:$E$349) -> 36.289 | D19: =MAX(Ocupados_Proy!$E$327:$E$349) -> 73.0764 | E19: =D19-C19 -> 36.7874 | F19: =INDEX(Ocupados_Proy!$A$327:$A$349,MATCH(C19,Ocupados_Proy!$E$327:$E$349,0)) -> Medellín | G19: =INDEX(Ocupados_Proy!$A$327:$A$349,MATCH(D19,Ocupados_Proy!$E$327:$E$349,0)) -> Quibdó | H19: =SUM(Ocupados_Proy!$F$327:$F$349) -> 7458486
A20: 2041 | B20: =SUMPRODUCT(Ocupados_Proy!$E$350:$E$372,Ocupados_Proy!$D$350:$D$372)/SUM(Ocupados_Proy!$D$350:$D$372) -> 46.860099 | C20: =MIN(Ocupados_Proy!$E$350:$E$372) -> 35.9323 | D20: =MAX(Ocupados_Proy!$E$350:$E$372) -> 72.7655 | E20: =D20-C20 -> 36.8332 | F20: =INDEX(Ocupados_Proy!$A$350:$A$372,MATCH(C20,Ocupados_Proy!$E$350:$E$372,0)) -> Medellín | G20: =INDEX(Ocupados_Proy!$A$350:$A$372,MATCH(D20,Ocupados_Proy!$E$350:$E$372,0)) -> Quibdó | H20: =SUM(Ocupados_Proy!$F$350:$F$372) -> 7395478.6
A21: 2042 | B21: =SUMPRODUCT(Ocupados_Proy!$E$373:$E$395,Ocupados_Proy!$D$373:$D$395)/SUM(Ocupados_Proy!$D$373:$D$395) -> 46.614078 | C21: =MIN(Ocupados_Proy!$E$373:$E$395) -> 35.5791 | D21: =MAX(Ocupados_Proy!$E$373:$E$395) -> 72.456 | E21: =D21-C21 -> 36.8769 | F21: =INDEX(Ocupados_Proy!$A$373:$A$395,MATCH(C21,Ocupados_Proy!$E$373:$E$395,0)) -> Medellín | G21: =INDEX(Ocupados_Proy!$A$373:$A$395,MATCH(D21,Ocupados_Proy!$E$373:$E$395,0)) -> Quibdó | H21: =SUM(Ocupados_Proy!$F$373:$F$395) -> 7327718.6

Sheet Historico_GEIH_2007-2026
A1: TASAS HISTÓRICAS DE INFORMALIDAD — DANE GEIH 2007-2026 | (% Ocupados Informales / Total Ocupados)
A3: Fuente: DANE — Gran Encuesta Integrada de Hogares (GEIH). 2007-2024: serie histórica existente. 2025: promedio simple de trimestres móviles Ene-mar a Oct-dic 2025 tomado de la hoja “Prop informalidad”. 2026: dato parcial Ene-mar 2026, no promedio anual.
A5: Ciudad | B5: 2007 | C5: 2008 | D5: 2009 | E5: 2010 | F5: 2011 | G5: 2012 | H5: 2013 | I5: 2014 | J5: 2015 | K5: 2016 | L5: 2017 | M5: 2018 | N5: 2019 | O5: 2020 | P5: 2021 | Q5: 2022 | R5: 2023 | S5: 2024 | T5: 2025 | U5: 2026
A6: Bogotá D.C. | B6: 47.8 | C6: 47.2 | D6: 46.8 | E6: 46.1 | F6: 45.5 | G6: 44.8 | H6: 44.2 | I6: 44.2 | J6: 43.8 | K6: 43.5 | L6: 43.1 | M6: 42.6 | N6: 42 | O6: 45.8 | P6: 44.2 | Q6: 42.9 | R6: 42.2 | S6: 41.8 | T6: 35.4649 | U6: 34.0393
A7: Medellín | B7: 50.2 | C7: 49.5 | D7: 48.8 | E7: 47.9 | F7: 47.1 | G7: 46.2 | H7: 45.3 | I7: 44.9 | J7: 44.5 | K7: 44.1 | L7: 43.5 | M7: 43.2 | N7: 42.7 | O7: 46.5 | P7: 45.1 | Q7: 43.8 | R7: 43.1 | S7: 42.5 | T7: 38.7395 | U7: 38.4318
A8: Cali | B8: 56.5 | C8: 55.8 | D8: 55.1 | E8: 54.5 | F8: 53.8 | G8: 53.1 | H8: 52.5 | I8: 52.2 | J8: 51.9 | K8: 51.4 | L8: 50.8 | M8: 50.3 | N8: 49.7 | O8: 53.2 | P8: 51.8 | Q8: 50.4 | R8: 49.7 | S8: 49.1 | T8: 46.4605 | U8: 47.0456
A9: Barranquilla | B9: 61.9 | C9: 61.2 | D9: 60.5 | E9: 59.8 | F9: 59.2 | G9: 58.4 | H9: 57.9 | I9: 57.8 | J9: 57.5 | K9: 57.1 | L9: 56.7 | M9: 56.2 | N9: 55.8 | O9: 59.5 | P9: 58.3 | Q9: 57 | R9: 56.4 | S9: 55.9 | T9: 52.7322 | U9: 51.6121
A10: Bucaramanga | B10: 69.2 | C10: 68.5 | D10: 67.8 | E10: 67.1 | F10: 66.4 | G10: 65.5 | H10: 64.8 | I10: 64.2 | J10: 63.8 | K10: 63.2 | L10: 62.8 | M10: 62.4 | N10: 61.8 | O10: 65.5 | P10: 64.5 | Q10: 63.3 | R10: 62.5 | S10: 62 | T10: 45.7197 | U10: 42.6957
A11: Manizales | B11: 56.1 | C11: 55.4 | D11: 54.7 | E11: 54.1 | F11: 53.4 | G11: 52.6 | H11: 52.1 | I11: 51.8 | J11: 51.5 | K11: 51 | L11: 50.5 | M11: 49.9 | N11: 49.4 | O11: 52.8 | P11: 51.5 | Q11: 50.4 | R11: 49.5 | S11: 49.1 | T11: 36.8349 | U11: 35.1318
A12: Pasto | B12: 73.8 | C12: 73.1 | D12: 72.5 | E12: 72 | F12: 71.4 | G12: 70.5 | H12: 70.2 | I12: 70.1 | J12: 69.9 | K12: 69.6 | L12: 69.2 | M12: 68.9 | N12: 68.5 | O12: 71.8 | P12: 70.8 | Q12: 69.7 | R12: 68.8 | S12: 68.4 | T12: 56.5371 | U12: 54.4881
A13: Pereira | B13: 63.5 | C13: 62.8 | D13: 62.1 | E13: 61.5 | F13: 60.8 | G13: 60 | H13: 59.5 | I13: 59.3 | J13: 59 | K13: 58.5 | L13: 58 | M13: 57.5 | N13: 57 | O13: 61 | P13: 59.8 | Q13: 58.6 | R13: 57.8 | S13: 57.3 | T13: 40.6873 | U13: 39.3332
A14: Cúcuta | B14: 76.9 | C14: 76.2 | D14: 75.5 | E14: 74.8 | F14: 74.1 | G14: 73.2 | H14: 72.5 | I14: 72 | J14: 71.6 | K14: 71.1 | L14: 70.7 | M14: 70.3 | N14: 69.8 | O14: 73.5 | P14: 72.5 | Q14: 71.3 | R14: 70.5 | S14: 70.1 | T14: 62.13 | U14: 62.2944
A15: Ibagué | B15: 66.1 | C15: 65.4 | D15: 64.7 | E15: 64.1 | F15: 63.4 | G15: 63 | H15: 62.5 | I15: 62.2 | J15: 62 | K15: 61.5 | L15: 61 | M15: 60.5 | N15: 60 | O15: 64 | P15: 62.9 | Q15: 61.8 | R15: 61.1 | S15: 60.6 | T15: 48.5406 | U15: 45.3417
A16: Montería | B16: 80.2 | C16: 79.5 | D16: 78.8 | E16: 78.2 | F16: 77.5 | G16: 77 | H16: 76.5 | I16: 76 | J16: 75.7 | K16: 75.2 | L16: 74.8 | M16: 74.4 | N16: 73.9 | O16: 77.5 | P16: 76.5 | Q16: 75.4 | R16: 74.5 | S16: 74.1 | T16: 61.6021 | U16: 55.8173
A17: Cartagena | B17: 61.5 | C17: 60.8 | D17: 60.2 | E17: 59.5 | F17: 58.8 | G17: 58.2 | H17: 57.8 | I17: 57.5 | J17: 57.2 | K17: 56.9 | L17: 56.5 | M17: 56.1 | N17: 55.6 | O17: 59.5 | P17: 58.2 | Q17: 57 | R17: 56.3 | S17: 55.8 | T17: 49.3058 | U17: 45.7121
... A31: Índice κₜ Lee-Carter (histórico) | B31: 1.357218 | C31: 1.12127 | D31: 0.890735 | E31: 0.662383 | F31: 0.417758 | G31: 0.163599 | H31: -0.031979 | I31: -0.132755 | J31: -0.246582 | K31: -0.402153 | L31: -0.568229 | M31: -0.72807 | N31: -0.918812 | O31: 0.443569 | P31: 0.007617 | Q31: -0.427199 | R31: -0.713197 | S31: -0.895172 | T31: -4.7149617 | U31: -5.6456896

Sheet Params_Lee-Carter
A1: PARÁMETROS DEL MODELO LEE-CARTER | SVD + ARIMA(0,1,0) con deriva
A4: A. BONDAD DE AJUSTE DEL MODELO
A5: Varianza explicada — 1er factor SVD | B5: 99.1% | C5: Un solo factor captura el 99.1% de la variación común entre ciudades
A6: Deriva de κₜ (drift anual) | B6: -0.132494 | C6: Valor negativo → tendencia secular de reducción de informalidad
A7: Desv. estándar innovaciones σε | B7: 0.3844 | C7: Base para cálculo de IC al 95%: ±1.96 × σε × √h
A8: Período de calibración | B8: 2007–2024 | C8: 18 observaciones anuales por ciudad
A9: Ciudades cubiertas | B9: 23 | C9: Cobertura GEIH — 13 ciudades originales + 10 ampliadas
A12: B. PARÁMETROS POR CIUDAD | aᶜ y bᶜ : hardcoded (modelo) | Tasas y cambio: fórmulas
A13: Ciudad | B13: aᶜ (media log-tasa) | C13: bᶜ (carga factorial) | D13: Tasa Base 2018 (%) | E13: Tasa Proy. 2026 (%) | F13: Cambio 2018→2042 (pp)
A14: Bogotá D.C. | B14: -0.813608 | C14: 0.058977 | D14: ='Historico_GEIH_2007-2026'!$M$6 -> 42.6 | E14: =Tasas_Informalidad_Proy!$B$6 -> 41.3942 | F14: =Tasas_Informalidad_Proy!$R$6-'Historico_GEIH_2007-2026'!$M$6 -> -6.0707
A15: Medellín | B15: -0.78886 | C15: 0.074557 | D15: ='Historico_GEIH_2007-2026'!$M$7 -> 43.2 | E15: =Tasas_Informalidad_Proy!$B$7 -> 41.6713 | F15: =Tasas_Informalidad_Proy!$R$7-'Historico_GEIH_2007-2026'!$M$7 -> -7.6209
A16: Cali | B16: -0.648566 | C16: 0.059125 | D16: ='Historico_GEIH_2007-2026'!$M$8 -> 50.3 | E16: =Tasas_Informalidad_Proy!$B$8 -> 48.8136 | F16: =Tasas_Informalidad_Proy!$R$8-'Historico_GEIH_2007-2026'!$M$8 -> -7.2367
A17: Barranquilla | B17: -0.542227 | C17: 0.04511 | D17: ='Historico_GEIH_2007-2026'!$M$9 -> 56.2 | E17: =Tasas_Informalidad_Proy!$B$9 -> 55.1804 | F17: =Tasas_Informalidad_Proy!$R$9-'Historico_GEIH_2007-2026'!$M$9 -> -6.0519
A18: Bucaramanga | B18: -0.435391 | C18: 0.050342 | D18: ='Historico_GEIH_2007-2026'!$M$10 -> 62.4 | E18: =Tasas_Informalidad_Proy!$B$10 -> 61.0305 | F18: =Tasas_Informalidad_Proy!$R$10-'Historico_GEIH_2007-2026'!$M$10 -> -7.5471
A19: Manizales | B19: -0.654906 | C19: 0.057507 | D19: ='Historico_GEIH_2007-2026'!$M$11 -> 49.9 | E19: =Tasas_Informalidad_Proy!$B$11 -> 48.5963 | F19: =Tasas_Informalidad_Proy!$R$11-'Historico_GEIH_2007-2026'!$M$11 -> -6.8812
A20: Pasto | B20: -0.349644 | C20: 0.032627 | D20: ='Historico_GEIH_2007-2026'!$M$12 -> 68.9 | E20: =Tasas_Informalidad_Proy!$B$12 -> 67.8754 | F20: =Tasas_Informalidad_Proy!$R$12-'Historico_GEIH_2007-2026'!$M$12 -> -5.5605
A21: Pereira | B21: -0.51689 | C21: 0.046493 | D21: ='Historico_GEIH_2007-2026'!$M$13 -> 57.5 | E21: =Tasas_Informalidad_Proy!$B$13 -> 56.5056 | F21: =Tasas_Informalidad_Proy!$R$13-'Historico_GEIH_2007-2026'!$M$13 -> -6.298
A22: Cúcuta | B22: -0.32078 | C22: 0.04289 | D22: ='Historico_GEIH_2007-2026'!$M$14 -> 70.3 | E22: =Tasas_Informalidad_Proy!$B$14 -> 69.0362 | F22: =Tasas_Informalidad_Proy!$R$14-'Historico_GEIH_2007-2026'!$M$14 -> -7.2638
A23: Ibagué | B23: -0.468771 | C23: 0.039823 | D23: ='Historico_GEIH_2007-2026'!$M$15 -> 60.5 | E23: =Tasas_Informalidad_Proy!$B$15 -> 59.7518 | F23: =Tasas_Informalidad_Proy!$R$15-'Historico_GEIH_2007-2026'!$M$15 -> -5.5854
A24: Montería | B24: -0.26911 | C24: 0.035441 | D24: ='Historico_GEIH_2007-2026'!$M$16 -> 74.4 | E24: =Tasas_Informalidad_Proy!$B$16 -> 73.328 | F24: =Tasas_Informalidad_Proy!$R$16-'Historico_GEIH_2007-2026'!$M$16 -> -6.3792
A25: Cartagena | B25: -0.545733 | C25: 0.043345 | D25: ='Historico_GEIH_2007-2026'!$M$17 -> 56.1 | E25: =Tasas_Informalidad_Proy!$B$17 -> 55.1 | F25: =Tasas_Informalidad_Proy!$R$17-'Historico_GEIH_2007-2026'!$M$17 -> -5.8374
A26: Villavicencio | B26: -0.458455 | C26: 0.040662 | D26: ='Historico_GEIH_2007-2026'!$M$18 -> 61.3 | E26: =Tasas_Informalidad_Proy!$B$18 -> 60.3126 | F26: =Tasas_Informalidad_Proy!$R$18-'Historico_GEIH_2007-2026'!$M$18 -> -5.9685
A27: Tunja | B27: -0.462474 | C27: 0.039098 | D27: ='Historico_GEIH_2007-2026'!$M$19 -> 61.2 | E27: =Tasas_Informalidad_Proy!$B$19 -> 60.1797 | F27: =Tasas_Informalidad_Proy!$R$19-'Historico_GEIH_2007-2026'!$M$19 -> -5.8071
A28: Florencia | B28: -0.25472 | C28: 0.033525 | D28: ='Historico_GEIH_2007-2026'!$M$20 -> 75.5 | E28: =Tasas_Informalidad_Proy!$B$20 -> 74.5564 | F28: =Tasas_Informalidad_Proy!$R$20-'Historico_GEIH_2007-2026'!$M$20 -> -6.0584
A29: Popayán | B29: -0.343482 | C29: 0.035332 | D29: ='Historico_GEIH_2007-2026'!$M$21 -> 69 | E29: =Tasas_Informalidad_Proy!$B$21 -> 68.081 | F29: =Tasas_Informalidad_Proy!$R$21-'Historico_GEIH_2007-2026'!$M$21 -> -5.832
A30: Valledupar | B30: -0.363356 | C30: 0.036926 | D30: ='Historico_GEIH_2007-2026'!$M$22 -> 67.6 | E30: =Tasas_Informalidad_Proy!$B$22 -> 66.6179 | F30: =Tasas_Informalidad_Proy!$R$22-'Historico_GEIH_2007-2026'!$M$22 -> -5.998
A31: Quibdó | B31: -0.216667 | C31: 0.032171 | D31: ='Historico_GEIH_2007-2026'!$M$23 -> 78.5 | E31: =Tasas_Informalidad_Proy!$B$23 -> 77.5699 | F31: =Tasas_Informalidad_Proy!$R$23-'Historico_GEIH_2007-2026'!$M$23 -> -6.044
A32: Neiva | B32: -0.402215 | C32: 0.037785 | D32: ='Historico_GEIH_2007-2026'!$M$24 -> 65 | E32: =Tasas_Informalidad_Proy!$B$24 -> 64.0151 | F32: =Tasas_Informalidad_Proy!$R$24-'Historico_GEIH_2007-2026'!$M$24 -> -5.9126
A33: Riohacha | B33: -0.284547 | C33: 0.034143 | D33: ='Historico_GEIH_2007-2026'!$M$25 -> 73.3 | E33: =Tasas_Informalidad_Proy!$B$25 -> 72.3136 | F33: =Tasas_Informalidad_Proy!$R$25-'Historico_GEIH_2007-2026'!$M$25 -> -6.0356
A34: Santa Marta | B34: -0.501186 | C34: 0.041965 | D34: ='Historico_GEIH_2007-2026'!$M$26 -> 58.7 | E34: =Tasas_Informalidad_Proy!$B$26 -> 57.7023 | F34: =Tasas_Informalidad_Proy!$R$26-'Historico_GEIH_2007-2026'!$M$26 -> -5.9093
A35: Armenia | B35: -0.565224 | C35: 0.045393 | D35: ='Historico_GEIH_2007-2026'!$M$27 -> 55 | E35: =Tasas_Informalidad_Proy!$B$27 -> 53.9082 | F35: =Tasas_Informalidad_Proy!$R$27-'Historico_GEIH_2007-2026'!$M$27 -> -6.0376
A36: Sincelejo | B36: -0.353498 | C36: 0.036763 | D36: ='Historico_GEIH_2007-2026'!$M$28 -> 68.3 | E36: =Tasas_Informalidad_Proy!$B$28 -> 67.2907 | F36: =Tasas_Informalidad_Proy!$R$28-'Historico_GEIH_2007-2026'!$M$28 -> -6.0544
A39: C. ÍNDICE TEMPORAL κₜ — HISTÓRICO (observado) Y PROYECTADO (ARIMA RWD)
A40: Año | B40: κₜ Observado | C40: κₜ Proyectado (central) | D40: κₜ IC Bajo 95% | E40: κₜ IC Alto 95% | F40: Tipo
A41: 2007 | B41: 1.357218 | F41: Observado
A42: 2008 | B42: 1.12127 | F42: Observado
A43: 2009 | B43: 0.890735 | F43: Observado
A44: 2010 | B44: 0.662383 | F44: Observado
A45: 2011 | B45: 0.417758 | F45: Observado
A46: 2012 | B46: 0.163599 | F46: Observado
...

Sheet Nota_Metodologica
A1: NOTA TÉCNICO-METODOLÓGICA — PROYECCIÓN DE TASAS DE INFORMALIDAD
A4: 1. OBJETIVO
A5: Proyectar las tasas de informalidad laboral para 23 ciudades colombianas en el horizonte 2026–2042, siguiendo los criterios metodológicos de la Actualización PPED 2025 del DANE (Proyecciones de Población y Estudios Demográficos, julio 2025).
A7: 2. FUENTES DE INFORMACIÓN
A8: • Insumo poblacional: DANE PPED 2025 — Archivo PPED-AreaSexoEdadMun-2018-2042_VP.xlsx. Proyecciones de PEA (15–64 años) por municipio, área, sexo y edades simples. • Tasas históricas: DANE — Gran Encuesta Integrada de Hogares (GEIH), promedios anuales 2007-2024. Criterio de informalidad: ocupados en establecimientos con 5 o menos trabajadores. • Referencia metodológica: DANE, Dirección de Censos y Demografía, Nota Técnica PPED Julio 2025.
A10: 3. MODELO LEE-CARTER ADAPTADO
A11: El modelo Lee-Carter (1992), utilizado por el DANE adaptado para proyectar tasas específicas de fecundidad (ver Nota Técnica PPED Jul-2025, sección 2.4), se aplica aquí a las tasas de informalidad laboral: ln(r_{c,t}) = a_c + b_c × κ_t + ε_{c,t} donde: • r_{c,t} = tasa de informalidad de la ciudad c en el año t • a_c = efecto de ciudad (media temporal del log de la tasa) • b_c = carga factorial (sensibilidad de cada ciudad al cambio temporal) • κ_t = índice temporal común (captura la tendencia secular) • ε_{c,t} = error idiosincrático ESTIMACIÓN: Descomposición en Valores Singulares (SVD) de la matriz de logs demediados. Se retiene el primer componente, que explica el 99.1% de la varianza total.
A13: 4. PROYECCIÓN DE κₜ — RANDOM WALK CON DERIVA (ARIMA(0,1,0))
A14: Siguiendo a Lee y Carter (1992) y al procedimiento del DANE para tasas específicas de fecundidad, el índice κₜ se proyecta mediante ARIMA(0,1,0) con intercepto: Δκ_t = d + ε_t, ε_t ~ N(0, σ²_ε) Deriva estimada: d = -0.132494 (valor negativo → informalidad tiende a bajar) σε = 0.3844 Intervalos de confianza al 95%: κ_{{T+h}} ± 1.96 × σε × √h
A16: 5. PEA COMO PROXY DE OCUPADOS — ACLARACIÓN CONCEPTUAL
A17: La tasa de informalidad se define estadísticamente sobre el total de ocupados (no sobre la PEA bruta). Sin embargo, dado que no se disponen de proyecciones independientes de ocupados para el horizonte 2026-2042, la PEA 15-64 del PPED se utiliza como denominador proxy: Ocupados Informales_{c,t} = PEA_{c,t} × r_{c,t} Ocupados Formales_{c,t} = PEA_{c,t} × (1 - r_{c,t}) Esta aproximación asume implícitamente que la tasa de participación laboral efectiva (ocupados/PEA) se mantiene estable a lo largo del horizonte de proyección. Los resultados deben interpretarse como estimaciones proyectadas, no como cifras definitivas.
A19: 6. CONVERGENCIA Y HETEROGENEIDAD ENTRE CIUDADES
... A26: • Lee, R.D. & Carter, L.R. (1992). Modeling and Forecasting U.S. Mortality. JASA, 87(419). • DANE (2025). Nota Técnica PPED — Proyecciones de Población, Actualización 2025. • DANE (2024). Gran Encuesta Integrada de Hogares — Mercado Laboral. Informalidad. • Azose, J.J. & Raftery, A.E. (2015). Bayesian Probabilistic Projection of Migration. Demography. • Rogers, A. (2015). Applied Multiregional Demography. Springer.
